Workbook
Name Analýza: 'Ceník prací'!$C$3
Name Diskont: 'Finanční analýza'!$B$3
Name Koeficient_korekce: 'Ceník prací'!$C$10
Name Konfigurace__vývoj: 'Ceník prací'!$C$4
Name Migrace: 'Ceník prací'!$C$5
Name Ostatní: 'Ceník prací'!$C$9
Name Práva: 'Ceník prací'!$C$6
Name Tvorba_dokumentace: 'Ceník prací'!$C$7
Name Vedení_projektu: 'Ceník prací'!$C$8

Sheet Licence - obecně
A1: Licenční a cenový model systému INS@sáček
A3: 1. | B3: Licence je pevná a lze ji jen rozšiřovat.
A4: 2. | B4: Licence zahrnuje přístup k funkčním/systémovým modulům a konkurenční "plnohodnotné" uživatelé (viz záložka "Licence - moduly").
A5: 3. | B5: Každá licence vždy zahrnuje "jádro systému" (na záložce "Licence - moduly" indikováno ve sloupci "Jádro systému" a označeno zelenou barvou).
A6: 4. | B6: Moduly nad rámec "jádra systému" je možné pořizovat a kombinovat bez omezení.
A7: 5. | B7: Vybrané moduly vyžadují pořízení návazných modulů, bez jejichž pořízení nebude systém korektně fungovat (na záložce "Licence - moduly" indikováno ve sloupci "Nutné pořídit návazný funkční blok..." a označením návazného modulu).
A8: 6. | B8: Obdobně existuje vazba mezi vybranými funkčními a systémovými moduly (na záložce "Licence - moduly" indikováno ve sloupci "Vazba na systémový modul" a označením návazného systémového modulu).
A9: 7. | B9: V systému lze založit libovolný počet uživatelů, ale jen ti, kteří mají přiřazenou licenci, mohou se systémem pracovat plnohodnotně (nejen číst, ale i modifikovat).
A10: 8. | B10: Uživatel bez licence má právo jen pro čtení položek.
A11: 9. | B11: "Jádro systému" obsahuje 5 konkurenčních "plnohodnotných" uživatelů.
A12: 10. | B12: Licence pro rožšíření počtu "plnohodnotných" uživatelů lze pořizovat jednotlivě nebo ve zvýhodněných balíčcích (viz záložka "Licence - moduly").
A13: 11. | B13: Součástí jádra systému je klient (aplikace) na platformě .NET. Otatní typy klientů je nutné pořídit samostatně (viz záložka "Licence - moduly").
A14: 12. | B14: Systém standardně podporuje jen české a anglické uživatelské rozhraní. Další jazykové mutace se objednávají samostatně (viz záložka "Celkem za implementaci").
... A25: 24. | B25: Poznámka: tento konfigurátor je inspirován praktickou zkušeností a jeho cílem je ukázat všechny aspekty implementace informačního systému. Slouží pro výukové účely a je jen na uživatelích, aby si pro případné praktické využití zvážili, které položky jsou pro ně relevantní.

Sheet Licence - moduly
A1: Funkční moduly (jen licence)
B3: Funkční blok | C3: Jádro systému | D3: Cena | E3: Nutné pořídit návazný funkční blok (mimo jádro) | F3: Vazba na systémový modul | G3: Pořídit | H3: Cena | I3: Nutné pořídit?
A4: Ekonomika | B4: Pokladna | C4: þ | D4: 50000 | G4: 1 | H4: =D4*G4 -> 50000
B5: Majetek | C5: þ | D5: 0 | G5: 1 | H5: =D5*G5 -> 0
B6: Vozový park | C6: ý | D6: 5000 | G6: 0 | H6: =D6*G6 -> 0 | I6: POZOR! Byl vybrán modul "Kniha jízd"
B7: Fakturace | C7: þ | D7: 0 | G7: 1 | H7: =D7*G7 -> 0
B8: Kniha jízd | C8: ý | D8: 5000 | E8: vozový park | G8: 0 | H8: =D8*G8 -> 0
A9: Obchod | B9: Zákazníci | C9: þ | D9: 0 | G9: 1 | H9: =D9*G9 -> 0
B10: Dodavatelé | C10: þ | D10: 0 | G10: 1 | H10: =D10*G10 -> 0
B11: CRM | C11: ý | D11: 20000 | G11: 1 | H11: =D11*G11 -> 20000
B12: Sklady | C12: þ | D12: 0 | G12: 1 | H12: =D12*G12 -> 0
B13: E-shop | C13: ý | D13: 15000 | E13: uživatelský portál | G13: 0 | H13: =D13*G13 -> 0
A14: Personalistika | B14: Lidské zdroje | C14: þ | D14: 0 | F14: Pro napojení na externí systémy, je třeba pořídit systémový modul "Identity systém" | G14: 1 | H14: =D14*G14 -> 0
B15: Organizační struktura | C15: þ | D15: 0 | G15: 1 | H15: =D15*G15 -> 0
B16: Docházka | C16: ý | D16: 5000 | G16: 1 | H16: =D16*G16 -> 5000
A17: Výroba | B17: Zdroje | C17: þ | D17: 0 | G17: 1 | H17: =D17*G17 -> 0
B18: Řízení výroby | C18: ý | D18: 15000 | E18: plánování výroby | G18: 0 | H18: =D18*G18 -> 0
B19: Plánování výroby | C19: ý | D19: 15000 | G19: 0 | H19: =D19*G19 -> 0 | I19: POZOR! Byl vybrán modul "Řízení výroby"
A20: Projekty | B20: Řízení projektů | C20: ý | D20: 15000 | G20: 0 | H20: =D20*G20 -> 0
B21: Workflow, úlohy | C21: ý | D21: 20000 | G21: 0 | H21: =D21*G21 -> 0
B22: Správa dokumentů | C22: ý | D22: 20000 | G22: 1 | H22: =D22*G22 -> 20000
B23: Komunikace | C23: ý | D23: 10000 | F23: Pro komunikovaci i mimo systém musíme pořídit systémový modul "Zasílání zpráv" | G23: 1 | H23: =D23*G23 -> 10000
A24: Služby | B24: Helpdesk | C24: ý | D24: 10000 | G24: 1 | H24: =D24*G24 -> 10000
B25: Dispečink | C25: ý | D25: 10000 | G25: 1 | H25: =D25*G25 -> 10000
B26: Servis | C26: ý | D26: 10000 | G26: 1 | H26: =D26*G26 -> 10000
A27: Reporting | B27: Business Intelligence | C27: ý | D27: 50000 | G27: 1 | H27: =D27*G27 -> 50000
B28: Uživatelský portál | C28: ý | D28: 40000 | F28: Součástí funkčního modulu "Uživatelský portál" je Webový klient | G28: 1 | H28: =D28*G28 -> 40000 | I28: POZOR! Byl vybrán modul "E-shop"
B29: Tvorba reportů | C29: þ | D29: 0 | G29: 1 | H29: =D29*G29 -> 0
A30: Vlastní vývoj | B30: Uživatelský vývoj | C30: ý | D30: 40000 | G30: 1 | H30: =D30*G30 -> 40000
B31: Webové služby | C31: ý | D31: 50000 | F31: Součástí funkčního modulu "Webové služby" je systémový modul API | G31: 1 | H31: =D31*G31 -> 50000
B32: Export/Import | C32: þ | D32: 0 | F32: Součástí funkčního bloku je systémový modul "Export/Import" | G32: 1 | H32: =D32*G32 -> 0
B33: Celkem za všechny funkční moduly: | D33: =SUM(D4:D32) -> 405000 | F33: Celkem za pořizované moduly: | H33: =SUM(H4:H32) -> 315000
A35: Systémové moduly (licence + instalace + základní konfigurace)
B36: Systémový modul | C36: Jádro systému | D36: Cena | F36: Vazba na funkční modul | G36: Pořídit | H36: Cena
A37: Systémový modul | B37: Identity management | C37: ý | D37: 10000 | G37: 1 | H37: =D37*G37 -> 10000
B38: Zasílání zpráv | C38: ý | D38: 10000 | G38: 1 | H38: =D38*G38 -> 10000
B39: Import/export | C39: þ | D39: 0 | G39: 1 | H39: =D39*G39 -> 0
B40: API | C40: ý | D40: 0 | F40: Lze pořídit jen s funkčním modulem "Webové služby" | G40: =G31 -> 1 | H40: =D40*G40 -> 0 | I40: Byl vybrán modul "Webové služby"
B41: Celkem za všechny systémové moduly: | D41: =SUM(D37:D40) -> 20000 | F41: Celkem za pořizované systémové moduly: | H41: =SUM(H37:H40) -> 20000
A43: Klienti
...

Sheet Ceník prací
B2: Typ práce | C2: Cena za člh (člověkohodinu) | D2: Poznámka
B3: Analýza/konzultace | C3: 1000 | D3: Cena za provedení analýzy požadavků uživatelů, jejich zdokumentování, navržení úprav systému a jejich předání, včetně zaškolení uživatelů.
B4: Konfigurace (vývoj) | C4: 1000 | D4: Cena za konfigurace a úpravy standardů systému + cena za vývoj nových funkčností. V našem případě uvažujeme, že pracovníci, provádějící analýzu jsou schopni provádět i konfiguraci a jednoduché úpravy. Náročnější vývoj provádí vývojáři.
B5: Migrace | C5: 1000 | D5: Cena za přípravu a provedení migrace dat do nového systému. V praxi lze zahrnout do analýzy a konfigurace.
B6: Práva | C6: 1000 | D6: Cena za identifikaci a nastavení uživatelských práv v novém systému. V praxi lze zahrnout do analýzy a konfigurace.
B7: Tvorba dokumentace | C7: 800 | D7: Cena za tvorbu uživatelské dokumentace.
B8: Vedení projektu | C8: 1500 | D8: Pracovník, zajišťující koordinaci a řízení projektu. Jak interně, tak i směrem k zákazníkovi.
B9: Ostatní | C9: 1000 | D9: Ceník za ostatní práce. Například instalace, napojení na externí Identity systém, poštovní server atd.
B10: Koeficient korekce práce | C10: 1.5 | D10: Koeficient, kterým se násobí odhady na zprovoznění jednotlivých modulů. Čím vyšší nejistota plyne, tím vyšší hodnotu je vhodné zvolit.

Sheet Moduly - práce celkem
B1: Modul | C1: Jádro systému | D1: Zprovoznění (člh) | E1: min. (člh) | F1: max. (člh) | G1: Orientační čas konfigurace modulu v člh | H1: Pořizováno | I1: Odhad konfigurace (člh) | J1: Odhad analýzy (člh) | K1: Odhad migrace (člh) | L1: Odhad práv (člh) | M1: Celkový odhad (člh) | N1: Cena
A2: Ekonomika | B2: Pokladna | C2: þ | D2: 0 | E2: 8 | F2: 32 | H2: ='[1]Licence - moduly'!G4 -> 1 | I2: 16 | J2: 16 | K2: 0 | L2: 4 | M2: =SUM(I2:L2) -> 36 | N2: =I2*Analýza+J2*Konfigurace__vývoj+K2*Migrace+L2*Práva -> 36000
B3: Majetek | C3: þ | D3: 0 | E3: 8 | F3: 32 | H3: ='[1]Licence - moduly'!G5 -> 1 | I3: 24 | J3: 20 | K3: 0 | L3: 4 | M3: =SUM(I3:L3) -> 48 | N3: =I3*Analýza+J3*Konfigurace__vývoj+K3*Migrace+L3*Práva -> 48000
B4: Vozový park | C4: ý | D4: 0 | E4: 4 | F4: 8 | H4: ='[1]Licence - moduly'!G6 -> 0 | I4: 0 | J4: 0 | K4: 0 | L4: 0 | M4: =SUM(I4:L4) -> 0 | N4: =I4*Analýza+J4*Konfigurace__vývoj+K4*Migrace+L4*Práva -> 0
B5: Fakturace | C5: þ | D5: 0 | E5: 4 | F5: 8 | H5: ='[1]Licence - moduly'!G7 -> 1 | I5: 8 | J5: 8 | K5: 0 | L5: 2 | M5: 18 | N5: =I5*Analýza+J5*Konfigurace__vývoj+K5*Migrace+L5*Práva -> 18000
B6: Kniha jízd | C6: ý | D6: 0 | E6: 8 | F6: 16 | H6: ='[1]Licence - moduly'!G8 -> 0 | I6: 0 | J6: 0 | K6: 0 | L6: 0 | M6: =SUM(I6:L6) -> 0 | N6: =I6*Analýza+J6*Konfigurace__vývoj+K6*Migrace+L6*Práva -> 0
A7: Obchod | B7: Zákazníci | C7: þ | D7: 0 | E7: 4 | F7: 8 | H7: ='[1]Licence - moduly'!G9 -> 1 | I7: 8 | J7: 8 | K7: 4 | L7: 2 | M7: =SUM(I7:L7) -> 22 | N7: =I7*Analýza+J7*Konfigurace__vývoj+K7*Migrace+L7*Práva -> 22000
B8: Dodavatelé | C8: þ | D8: 0 | E8: 4 | F8: 8 | H8: ='[1]Licence - moduly'!G10 -> 1 | I8: 8 | J8: 8 | K8: 4 | L8: 2 | M8: =SUM(I8:L8) -> 22 | N8: =I8*Analýza+J8*Konfigurace__vývoj+K8*Migrace+L8*Práva -> 22000
B9: CRM | C9: ý | D9: 0 | E9: 8 | F9: 32 | H9: ='[1]Licence - moduly'!G11 -> 1 | I9: 32 | J9: 28 | K9: 8 | L9: 8 | M9: =SUM(I9:L9) -> 76 | N9: =I9*Analýza+J9*Konfigurace__vývoj+K9*Migrace+L9*Práva -> 76000
B10: Sklady | C10: þ | D10: 0 | E10: 8 | F10: 24 | H10: ='[1]Licence - moduly'!G12 -> 1 | I10: 24 | J10: 24 | K10: 8 | L10: 4 | M10: =SUM(I10:L10) -> 60 | N10: =I10*Analýza+J10*Konfigurace__vývoj+K10*Migrace+L10*Práva -> 60000
B11: E-shop | C11: ý | D11: 8 | E11: 8 | F11: 80 | G11: min. = jednoduchý eshop, max. = komplexnější funkčnost | H11: ='[1]Licence - moduly'!G13 -> 0 | I11: 0 | J11: 0 | K11: 0 | L11: 0 | M11: =SUM(I11:L11) -> 0 | N11: =I11*Analýza+J11*Konfigurace__vývoj+K11*Migrace+L11*Práva -> 0 | O11: poznamka "díky tomu, že budeme mít webshop... zvýšíme první rok obrat o 10 %" Koci si zminil, ze e shop bude, ale neni to porizeny though
A12: Personalistika | B12: Lidské zdroje | C12: þ | D12: 0 | E12: 1 | F12: 16 | H12: ='[1]Licence - moduly'!G14 -> 1 | I12: 16 | J12: 16 | K12: 4 | L12: 4 | M12: =SUM(I12:L12) -> 40 | N12: =I12*Analýza+J12*Konfigurace__vývoj+K12*Migrace+L12*Práva -> 40000
B13: Organizační struktura | C13: þ | D13: 0 | E13: 1 | F13: 8 | H13: ='[1]Licence - moduly'!G15 -> 1 | I13: 8 | J13: 8 | K13: 0 | L13: 4 | M13: =SUM(I13:L13) -> 20 | N13: =I13*Analýza+J13*Konfigurace__vývoj+K13*Migrace+L13*Práva -> 20000
B14: Docházka | C14: ý | D14: 0 | E14: 8 | F14: 24 | H14: 1 | I14: 24 | J14: 20 | K14: 0 | L14: 4 | M14: =SUM(I14:L14) -> 48 | N14: =I14*Analýza+J14*Konfigurace__vývoj+K14*Migrace+L14*Práva -> 48000
A15: Výroba | B15: Zdroje | C15: þ | D15: 0 | E15: 1 | F15: 8 | H15: ='[1]Licence - moduly'!G17 -> 1 | I15: 8 | J15: 8 | K15: 0 | L15: 4 | M15: =SUM(I15:L15) -> 20 | N15: =I15*Analýza+J15*Konfigurace__vývoj+K15*Migrace+L15*Práva -> 20000
B16: Řízení výroby | C16: ý | D16: 0 | E16: 8 | F16: 32 | H16: ='[1]Licence - moduly'!G18 -> 0 | I16: 0 | J16: 0 | K16: 0 | L16: 0 | M16: =SUM(I16:L16) -> 0 | N16: =I16*Analýza+J16*Konfigurace__vývoj+K16*Migrace+L16*Práva -> 0
B17: Plánování výroby | C17: ý | D17: 0 | E17: 8 | F17: 32 | H17: ='[1]Licence - moduly'!G19 -> 0 | I17: 0 | J17: 0 | K17: 0 | L17: 0 | M17: =SUM(I17:L17) -> 0 | N17: =I17*Analýza+J17*Konfigurace__vývoj+K17*Migrace+L17*Práva -> 0
A18: Projekty | B18: Řízení projektů | C18: ý | D18: 0 | E18: 8 | F18: 32 | H18: ='[1]Licence - moduly'!G20 -> 0 | I18: 0 | J18: 0 | K18: 0 | L18: 0 | M18: =SUM(I18:L18) -> 0 | N18: =I18*Analýza+J18*Konfigurace__vývoj+K18*Migrace+L18*Práva -> 0
B19: Workflow, úlohy | C19: ý | D19: 0 | E19: 1 | F19: 16 | G19: počítáno za jedno workflow, respektive úkol | H19: 0 | I19: 0 | J19: 0 | K19: 0 | L19: 0 | M19: =SUM(I19:L19) -> 0 | N19: =I19*Analýza+J19*Konfigurace__vývoj+K19*Migrace+L19*Práva -> 0
B20: Správa dokumentů | C20: ý | D20: 0 | E20: 8 | F20: 16 | H20: 1 | I20: 16 | J20: 16 | K20: 0 | L20: 4 | M20: =SUM(I20:L20) -> 36 | N20: =I20*Analýza+J20*Konfigurace__vývoj+K20*Migrace+L20*Práva -> 36000
B21: Komunikace | C21: ý | D21: 0 | E21: 8 | F21: 16 | H21: 1 | I21: 16 | J21: 16 | K21: 0 | L21: 4 | M21: =SUM(I21:L21) -> 36 | N21: =I21*Analýza+J21*Konfigurace__vývoj+K21*Migrace+L21*Práva -> 36000
A22: Služby | B22: Helpdesk | C22: ý | D22: 0 | E22: 8 | F22: 32 | H22: ='[1]Licence - moduly'!G24 -> 1 | I22: 24 | J22: 24 | K22: 0 | L22: 4 | M22: =SUM(I22:L22) -> 52 | N22: =I22*Analýza+J22*Konfigurace__vývoj+K22*Migrace+L22*Práva -> 52000
B23: Dispečink | C23: ý | D23: 0 | E23: 8 | F23: 32 | H23: 1 | I23: 32 | J23: 28 | K23: 0 | L23: 4 | M23: =SUM(I23:L23) -> 64 | N23: =I23*Analýza+J23*Konfigurace__vývoj+K23*Migrace+L23*Práva -> 64000
B24: Servis | C24: ý | D24: 0 | E24: 8 | F24: 32 | H24: ='[1]Licence - moduly'!G26 -> 1 | I24: 32 | J24: 32 | K24: 0 | L24: 4 | M24: =SUM(I24:L24) -> 68 | N24: =I24*Analýza+J24*Konfigurace__vývoj+K24*Migrace+L24*Práva -> 68000
A25: Reporting | B25: Business Intelligence | C25: ý | D25: 16 | E25: 40 | F25: 120 | G25: Počítáno dle složitosti implementovaných analýz | H25: 1 | I25: 80 | J25: 80 | K25: 0 | L25: 8 | M25: =SUM(I25:L25) -> 168 | N25: =I25*Analýza+J25*Konfigurace__vývoj+K25*Migrace+L25*Práva -> 168000
B26: Uživatelský portál | C26: ý | D26: 8 | E26: 4 | F26: 40 | G26: min. = jednoduchá agenda, max. = složitější sada stránek | H26: 1 | I26: 40 | J26: 32 | K26: 0 | L26: 4 | M26: =SUM(I26:L26) -> 76 | N26: =I26*Analýza+J26*Konfigurace__vývoj+K26*Migrace+L26*Práva -> 76000
B27: Tvorba reportů | C27: þ | D27: 0 | E27: 1 | F27: 32 | G27: Počítáno za jeden report | H27: ='[1]Licence - moduly'!G29 -> 1 | I27: 24 | J27: 24 | K27: 0 | L27: 4 | M27: =SUM(I27:L27) -> 52 | N27: =I27*Analýza+J27*Konfigurace__vývoj+K27*Migrace+L27*Práva -> 52000
A28: Vlastní vývoj | B28: Uživatelský vývoj | C28: ý | D28: 0 | E28: ? | F28: ? | G28: Individuálně dle rozsahu a složitosti nových funkčností | H28: 1 | I28: 40 | J28: 40 | K28: 0 | L28: 4 | M28: =SUM(I28:L28) -> 84 | N28: =I28*Analýza+J28*Konfigurace__vývoj+K28*Migrace+L28*Práva -> 84000
B29: Webové služby | C29: ý | D29: 0 | E29: 4 | F29: 24 | G29: Počítáno za jedno připojení | H29: 1 | I29: 24 | J29: 20 | K29: 0 | L29: 0 | M29: =SUM(I29:L29) -> 44 | N29: =I29*Analýza+J29*Konfigurace__vývoj+K29*Migrace+L29*Práva -> 44000
B30: Export/Import | C30: þ | D30: 0 | E30: 1 | F30: 24 | G30: Počítáno za jeden export/import | H30: ='[1]Licence - moduly'!G32 -> 1 | I30: 16 | J30: 16 | K30: 0 | L30: 0 | M30: =SUM(I30:L30) -> 32 | N30: =I30*Analýza+J30*Konfigurace__vývoj+K30*Migrace+L30*Práva -> 32000
K31: Celkem: | M31: =SUM(M2:M30) -> 1122 | N31: =SUM(N2:N30) -> 1122000
K32: Po korekci: | M32: =M31*Koeficient_korekce -> 1683 | N32: =N31*Koeficient_korekce -> 1683000
A34: Poznámka: uvedené hodiny jsou spíše pro orientaci. V praxi je vždy nutné čas konzultovat s lidmi, kteří dobře systém znají a na základě požadavku uživatelů jsou schopni dát přesnější odhad. Na analýzu konrétních požadavků je vhodné počítat s cca. 0,5 - 1,5 času na konfiguraci. Záleží na složitosti požadavku. U jednodušších požadavků je vhodné počítat s dolní hranicí, u nejasných s horní. Týká se to jak analýzy, tak i konfigurace. K celkovému času je vhodné přidat i rezervu cca. 50% na propojení a vzájemnou koordinaci mezi moduly + konfigurace základu.Stejně tak není součástí hodin migrace dat a zaškolení. U migrace dat je vždy nutné zvážit, zda si ji zákazník udělá sám, zadá data ručně nebo ve spolupráci s námi provede analýzu současných dat, vyčištění, konsolidaci, nahrání a kontrolu. Dle požadavků a způsobu provedení je vhodné na migraci nutné uvažovat od 0,5 až po 1,5 času, věnovaného konfiguraci agendy. Obdobně je vhodné uvažovat o nastavení přístupových práv. Systém je založený na rolích a umožňuje přiřazovat jak vetikální, tak i horizontální práva. Tj. práva k agendám a položkám agend.

Sheet Moduly - práce etapy
B1: Modul | C1: Jádro systému | D1: Zprovoznění (člh) | E1: min. (člh) | F1: max. (člh) | G1: Orientační čas konfigurace modulu v člh | H1: Pořizováno | I1: Odhad konfigurace (člh) | J1: Konfigurace Etapa 1 (člh) | K1: Konfigurace Etapa 2 (člh) | L1: Odhad analýzy (člh) | M1: Analýza Etapa 1 (člh) | N1: Analýza Etapa 2 (člh) | O1: Odhad migrace (člh) | P1: Migrace Etapa 1 (člh) | Q1: Migrace Etapa 2 (člh) | R1: Odhad práv (člh) | S1: Práva Etapa 1 (člh) | T1: Práva Etapa 2 (člh) | U1: Celkový odhad (člh) | V1: Cena za Etapu 1 | W1: Cena za Etapu2 | X1: Celková cena
A2: Ekonomika | B2: Pokladna | C2: þ | D2: 0 | E2: 8 | F2: 16 | H2: ='Licence - moduly'!G4 -> 1 | I2: ='Moduly - práce celkem'!I2 -> 16 | J2: 16 | K2: 0 | L2: ='Moduly - práce celkem'!J2 -> 16 | M2: 16 | N2: 0 | O2: ='Moduly - práce celkem'!K2 -> 0 | P2: 0 | Q2: 0 | R2: ='Moduly - práce celkem'!L2 -> 4 | S2: 4 | T2: 0 | U2: =I2+L2+O2+R2 -> 36 | V2: =M2*Analýza+J2*Konfigurace__vývoj+P2*Migrace+S2*Práva -> 36000 | W2: =N2*Analýza+K2*Konfigurace__vývoj+Q2*Migrace+T2*Práva -> 0 | X2: =L2*Analýza+I2*Konfigurace__vývoj+O2*Migrace+R2*Práva -> 36000
B3: Majetek | C3: þ | D3: 0 | E3: 8 | F3: 32 | H3: ='Licence - moduly'!G5 -> 1 | I3: ='Moduly - práce celkem'!I3 -> 24 | J3: 24 | K3: 0 | L3: ='Moduly - práce celkem'!J3 -> 20 | M3: 20 | N3: 0 | O3: ='Moduly - práce celkem'!K3 -> 0 | P3: 0 | Q3: 0 | R3: ='Moduly - práce celkem'!L3 -> 4 | S3: 4 | T3: 0 | U3: =I3+L3+O3+R3 -> 48 | V3: =M3*Analýza+J3*Konfigurace__vývoj+P3*Migrace+S3*Práva -> 48000 | W3: =N3*Analýza+K3*Konfigurace__vývoj+Q3*Migrace+T3*Práva -> 0 | X3: =L3*Analýza+I3*Konfigurace__vývoj+O3*Migrace+R3*Práva -> 48000
B4: Vozový park | C4: ý | D4: 0 | E4: 4 | F4: 8 | H4: ='Licence - moduly'!G6 -> 0 | I4: ='Moduly - práce celkem'!I4 -> 0 | J4: 0 | K4: 0 | L4: ='Moduly - práce celkem'!J4 -> 0 | M4: 0 | N4: 0 | O4: ='Moduly - práce celkem'!K4 -> 0 | P4: 0 | Q4: 0 | R4: ='Moduly - práce celkem'!L4 -> 0 | S4: 0 | T4: 0 | U4: =I4+L4+O4+R4 -> 0 | V4: =M4*Analýza+J4*Konfigurace__vývoj+P4*Migrace+S4*Práva -> 0 | W4: =N4*Analýza+K4*Konfigurace__vývoj+Q4*Migrace+T4*Práva -> 0 | X4: =L4*Analýza+I4*Konfigurace__vývoj+O4*Migrace+R4*Práva -> 0
B5: Fakturace | C5: þ | D5: 0 | E5: 4 | F5: 8 | H5: ='Licence - moduly'!G7 -> 1 | I5: ='Moduly - práce celkem'!I5 -> 8 | J5: 8 | K5: 0 | L5: ='Moduly - práce celkem'!J5 -> 8 | M5: 8 | N5: 0 | O5: ='Moduly - práce celkem'!K5 -> 0 | P5: 0 | Q5: 0 | R5: ='Moduly - práce celkem'!L5 -> 2 | S5: 2 | T5: 0 | U5: =I5+L5+O5+R5 -> 18 | V5: =M5*Analýza+J5*Konfigurace__vývoj+P5*Migrace+S5*Práva -> 18000 | W5: =N5*Analýza+K5*Konfigurace__vývoj+Q5*Migrace+T5*Práva -> 0 | X5: =L5*Analýza+I5*Konfigurace__vývoj+O5*Migrace+R5*Práva -> 18000
B6: Kniha jízd | C6: ý | D6: 0 | E6: 8 | F6: 16 | H6: ='Licence - moduly'!G8 -> 0 | I6: ='Moduly - práce celkem'!I6 -> 0 | J6: 0 | K6: 0 | L6: ='Moduly - práce celkem'!J6 -> 0 | M6: 0 | N6: 0 | O6: ='Moduly - práce celkem'!K6 -> 0 | P6: 0 | Q6: 0 | R6: ='Moduly - práce celkem'!L6 -> 0 | S6: 0 | T6: 0 | U6: =I6+L6+O6+R6 -> 0 | V6: =M6*Analýza+J6*Konfigurace__vývoj+P6*Migrace+S6*Práva -> 0 | W6: =N6*Analýza+K6*Konfigurace__vývoj+Q6*Migrace+T6*Práva -> 0 | X6: =L6*Analýza+I6*Konfigurace__vývoj+O6*Migrace+R6*Práva -> 0
A7: Obchod | B7: Zákazníci | C7: þ | D7: 0 | E7: 4 | F7: 8 | H7: ='Licence - moduly'!G9 -> 1 | I7: ='Moduly - práce celkem'!I7 -> 8 | J7: 8 | K7: 0 | L7: ='Moduly - práce celkem'!J7 -> 8 | M7: 8 | N7: 0 | O7: ='Moduly - práce celkem'!K7 -> 4 | P7: 4 | Q7: 0 | R7: ='Moduly - práce celkem'!L7 -> 2 | S7: 2 | T7: 0 | U7: =I7+L7+O7+R7 -> 22 | V7: =M7*Analýza+J7*Konfigurace__vývoj+P7*Migrace+S7*Práva -> 22000 | W7: =N7*Analýza+K7*Konfigurace__vývoj+Q7*Migrace+T7*Práva -> 0 | X7: =L7*Analýza+I7*Konfigurace__vývoj+O7*Migrace+R7*Práva -> 22000
B8: Dodavatelé | C8: þ | D8: 0 | E8: 4 | F8: 8 | H8: ='Licence - moduly'!G10 -> 1 | I8: ='Moduly - práce celkem'!I8 -> 8 | J8: 8 | K8: 0 | L8: ='Moduly - práce celkem'!J8 -> 8 | M8: 8 | N8: 0 | O8: ='Moduly - práce celkem'!K8 -> 4 | P8: 4 | Q8: 0 | R8: ='Moduly - práce celkem'!L8 -> 2 | S8: 2 | T8: 0 | U8: =I8+L8+O8+R8 -> 22 | V8: =M8*Analýza+J8*Konfigurace__vývoj+P8*Migrace+S8*Práva -> 22000 | W8: =N8*Analýza+K8*Konfigurace__vývoj+Q8*Migrace+T8*Práva -> 0 | X8: =L8*Analýza+I8*Konfigurace__vývoj+O8*Migrace+R8*Práva -> 22000
B9: CRM | C9: ý | D9: 0 | E9: 8 | F9: 32 | H9: ='Licence - moduly'!G11 -> 1 | I9: ='Moduly - práce celkem'!I9 -> 32 | J9: 32 | K9: 0 | L9: ='Moduly - práce celkem'!J9 -> 28 | M9: 28 | N9: 0 | O9: ='Moduly - práce celkem'!K9 -> 8 | P9: 8 | Q9: 0 | R9: ='Moduly - práce celkem'!L9 -> 8 | S9: 8 | T9: 0 | U9: =I9+L9+O9+R9 -> 76 | V9: =M9*Analýza+J9*Konfigurace__vývoj+P9*Migrace+S9*Práva -> 76000 | W9: =N9*Analýza+K9*Konfigurace__vývoj+Q9*Migrace+T9*Práva -> 0 | X9: =L9*Analýza+I9*Konfigurace__vývoj+O9*Migrace+R9*Práva -> 76000
B10: Sklady | C10: þ | D10: 0 | E10: 8 | F10: 24 | H10: ='Licence - moduly'!G12 -> 1 | I10: ='Moduly - práce celkem'!I10 -> 24 | J10: 24 | K10: 0 | L10: ='Moduly - práce celkem'!J10 -> 24 | M10: 24 | N10: 0 | O10: ='Moduly - práce celkem'!K10 -> 8 | P10: 8 | Q10: 0 | R10: ='Moduly - práce celkem'!L10 -> 4 | S10: 4 | T10: 0 | U10: =I10+L10+O10+R10 -> 60 | V10: =M10*Analýza+J10*Konfigurace__vývoj+P10*Migrace+S10*Práva -> 60000 | W10: =N10*Analýza+K10*Konfigurace__vývoj+Q10*Migrace+T10*Práva -> 0 | X10: =L10*Analýza+I10*Konfigurace__vývoj+O10*Migrace+R10*Práva -> 60000
B11: E-shop | C11: ý | D11: 8 | E11: 8 | F11: 80 | G11: min. = jednoduchý eshop, max. = komplexnější funkčnost | H11: ='Licence - moduly'!G13 -> 0 | I11: ='Moduly - práce celkem'!I11 -> 0 | J11: 0 | K11: 0 | L11: ='Moduly - práce celkem'!J11 -> 0 | M11: 0 | N11: 0 | O11: ='Moduly - práce celkem'!K11 -> 0 | P11: 0 | Q11: 0 | R11: ='Moduly - práce celkem'!L11 -> 0 | S11: 0 | T11: 0 | U11: =I11+L11+O11+R11 -> 0 | V11: =M11*Analýza+J11*Konfigurace__vývoj+P11*Migrace+S11*Práva -> 0 | W11: =N11*Analýza+K11*Konfigurace__vývoj+Q11*Migrace+T11*Práva -> 0 | X11: =L11*Analýza+I11*Konfigurace__vývoj+O11*Migrace+R11*Práva -> 0
A12: Personalistika | B12: Lidské zdroje | C12: þ | D12: 0 | E12: 1 | F12: 16 | H12: ='Licence - moduly'!G14 -> 1 | I12: ='Moduly - práce celkem'!I12 -> 16 | J12: 16 | K12: 0 | L12: ='Moduly - práce celkem'!J12 -> 16 | M12: 16 | N12: 0 | O12: ='Moduly - práce celkem'!K12 -> 4 | P12: 4 | Q12: 0 | R12: ='Moduly - práce celkem'!L12 -> 4 | S12: 4 | T12: 0 | U12: =I12+L12+O12+R12 -> 40 | V12: =M12*Analýza+J12*Konfigurace__vývoj+P12*Migrace+S12*Práva -> 40000 | W12: =N12*Analýza+K12*Konfigurace__vývoj+Q12*Migrace+T12*Práva -> 0 | X12: =L12*Analýza+I12*Konfigurace__vývoj+O12*Migrace+R12*Práva -> 40000
B13: Organizační struktura | C13: þ | D13: 0 | E13: 1 | F13: 8 | H13: ='Licence - moduly'!G15 -> 1 | I13: ='Moduly - práce celkem'!I13 -> 8 | J13: 8 | K13: 0 | L13: ='Moduly - práce celkem'!J13 -> 8 | M13: 8 | N13: 0 | O13: ='Moduly - práce celkem'!K13 -> 0 | P13: 0 | Q13: 0 | R13: ='Moduly - práce celkem'!L13 -> 4 | S13: 4 | T13: 0 | U13: =I13+L13+O13+R13 -> 20 | V13: =M13*Analýza+J13*Konfigurace__vývoj+P13*Migrace+S13*Práva -> 20000 | W13: =N13*Analýza+K13*Konfigurace__vývoj+Q13*Migrace+T13*Práva -> 0 | X13: =L13*Analýza+I13*Konfigurace__vývoj+O13*Migrace+R13*Práva -> 20000
B14: Docházka | C14: ý | D14: 0 | E14: 8 | F14: 24 | H14: 1 | I14: ='Moduly - práce celkem'!I14 -> 24 | J14: 24 | K14: 0 | L14: ='Moduly - práce celkem'!J14 -> 20 | M14: 20 | N14: 0 | O14: ='Moduly - práce celkem'!K14 -> 0 | P14: 0 | Q14: 0 | R14: ='Moduly - práce celkem'!L14 -> 4 | S14: 4 | T14: 0 | U14: =I14+L14+O14+R14 -> 48 | V14: =M14*Analýza+J14*Konfigurace__vývoj+P14*Migrace+S14*Práva -> 48000 | W14: =N14*Analýza+K14*Konfigurace__vývoj+Q14*Migrace+T14*Práva -> 0 | X14: =L14*Analýza+I14*Konfigurace__vývoj+O14*Migrace+R14*Práva -> 48000
A15: Výroba | B15: Zdroje | C15: þ | D15: 0 | E15: 1 | F15: 8 | H15: ='Licence - moduly'!G17 -> 1 | I15: ='Moduly - práce celkem'!I15 -> 8 | J15: 8 | K15: 0 | L15: ='Moduly - práce celkem'!J15 -> 8 | M15: 8 | N15: 0 | O15: ='Moduly - práce celkem'!K15 -> 0 | P15: 0 | Q15: 0 | R15: ='Moduly - práce celkem'!L15 -> 4 | S15: 4 | T15: 0 | U15: =I15+L15+O15+R15 -> 20 | V15: =M15*Analýza+J15*Konfigurace__vývoj+P15*Migrace+S15*Práva -> 20000 | W15: =N15*Analýza+K15*Konfigurace__vývoj+Q15*Migrace+T15*Práva -> 0 | X15: =L15*Analýza+I15*Konfigurace__vývoj+O15*Migrace+R15*Práva -> 20000
B16: Řízení výroby | C16: ý | D16: 0 | E16: 8 | F16: 32 | H16: ='Licence - moduly'!G18 -> 0 | I16: ='Moduly - práce celkem'!I16 -> 0 | J16: 0 | K16: 0 | L16: ='Moduly - práce celkem'!J16 -> 0 | M16: 0 | N16: 0 | O16: ='Moduly - práce celkem'!K16 -> 0 | P16: 0 | Q16: 0 | R16: ='Moduly - práce celkem'!L16 -> 0 | S16: 0 | T16: 0 | U16: =I16+L16+O16+R16 -> 0 | V16: =M16*Analýza+J16*Konfigurace__vývoj+P16*Migrace+S16*Práva -> 0 | W16: =N16*Analýza+K16*Konfigurace__vývoj+Q16*Migrace+T16*Práva -> 0 | X16: =L16*Analýza+I16*Konfigurace__vývoj+O16*Migrace+R16*Práva -> 0
B17: Plánování výroby | C17: ý | D17: 0 | E17: 8 | F17: 32 | H17: ='Licence - moduly'!G19 -> 0 | I17: ='Moduly - práce celkem'!I17 -> 0 | J17: 0 | K17: 0 | L17: ='Moduly - práce celkem'!J17 -> 0 | M17: 0 | N17: 0 | O17: ='Moduly - práce celkem'!K17 -> 0 | P17: 0 | Q17: 0 | R17: ='Moduly - práce celkem'!L17 -> 0 | S17: 0 | T17: 0 | U17: =I17+L17+O17+R17 -> 0 | V17: =M17*Analýza+J17*Konfigurace__vývoj+P17*Migrace+S17*Práva -> 0 | W17: =N17*Analýza+K17*Konfigurace__vývoj+Q17*Migrace+T17*Práva -> 0 | X17: =L17*Analýza+I17*Konfigurace__vývoj+O17*Migrace+R17*Práva -> 0
A18: Projekty | B18: Řízení projektů | C18: ý | D18: 0 | E18: 8 | F18: 32 | H18: ='Licence - moduly'!G20 -> 0 | I18: ='Moduly - práce celkem'!I18 -> 0 | J18: 0 | K18: 0 | L18: ='Moduly - práce celkem'!J18 -> 0 | M18: 0 | N18: 0 | O18: ='Moduly - práce celkem'!K18 -> 0 | P18: 0 | Q18: 0 | R18: ='Moduly - práce celkem'!L18 -> 0 | S18: 0 | T18: 0 | U18: =I18+L18+O18+R18 -> 0 | V18: =M18*Analýza+J18*Konfigurace__vývoj+P18*Migrace+S18*Práva -> 0 | W18: =N18*Analýza+K18*Konfigurace__vývoj+Q18*Migrace+T18*Práva -> 0 | X18: =L18*Analýza+I18*Konfigurace__vývoj+O18*Migrace+R18*Práva -> 0
B19: Workflow, úlohy | C19: ý | D19: 0 | E19: 1 | F19: 16 | G19: počítáno za jedno workflow, respektive úkol | H19: ='Licence - moduly'!G21 -> 0 | I19: ='Moduly - práce celkem'!I19 -> 0 | J19: 0 | K19: 0 | L19: ='Moduly - práce celkem'!J19 -> 0 | M19: 0 | N19: 0 | O19: ='Moduly - práce celkem'!K19 -> 0 | P19: 0 | Q19: 0 | R19: ='Moduly - práce celkem'!L19 -> 0 | S19: 0 | T19: 0 | U19: =I19+L19+O19+R19 -> 0 | V19: =M19*Analýza+J19*Konfigurace__vývoj+P19*Migrace+S19*Práva -> 0 | W19: =N19*Analýza+K19*Konfigurace__vývoj+Q19*Migrace+T19*Práva -> 0 | X19: =L19*Analýza+I19*Konfigurace__vývoj+O19*Migrace+R19*Práva -> 0
B20: Správa dokumentů | C20: ý | D20: 0 | E20: 8 | F20: 16 | H20: ='Licence - moduly'!G22 -> 1 | I20: ='Moduly - práce celkem'!I20 -> 16 | J20: 16 | K20: 0 | L20: ='Moduly - práce celkem'!J20 -> 16 | M20: 16 | N20: 0 | O20: ='Moduly - práce celkem'!K20 -> 0 | P20: 0 | Q20: 0 | R20: ='Moduly - práce celkem'!L20 -> 4 | S20: 4 | T20: 0 | U20: =I20+L20+O20+R20 -> 36 | V20: =M20*Analýza+J20*Konfigurace__vývoj+P20*Migrace+S20*Práva -> 36000 | W20: =N20*Analýza+K20*Konfigurace__vývoj+Q20*Migrace+T20*Práva -> 0 | X20: =L20*Analýza+I20*Konfigurace__vývoj+O20*Migrace+R20*Práva -> 36000
B21: Komunikace | C21: ý | D21: 0 | E21: 8 | F21: 16 | H21: ='Licence - moduly'!G23 -> 1 | I21: ='Moduly - práce celkem'!I21 -> 16 | J21: 16 | K21: 0 | L21: ='Moduly - práce celkem'!J21 -> 16 | M21: 16 | N21: 0 | O21: ='Moduly - práce celkem'!K21 -> 0 | P21: 0 | Q21: 0 | R21: ='Moduly - práce celkem'!L21 -> 4 | S21: 4 | T21: 0 | U21: =I21+L21+O21+R21 -> 36 | V21: =M21*Analýza+J21*Konfigurace__vývoj+P21*Migrace+S21*Práva -> 36000 | W21: =N21*Analýza+K21*Konfigurace__vývoj+Q21*Migrace+T21*Práva -> 0 | X21: =L21*Analýza+I21*Konfigurace__vývoj+O21*Migrace+R21*Práva -> 36000
A22: Služby | B22: Helpdesk | C22: ý | D22: 0 | E22: 8 | F22: 32 | H22: ='Licence - moduly'!G24 -> 1 | I22: ='Moduly - práce celkem'!I22 -> 24 | J22: 24 | K22: 0 | L22: ='Moduly - práce celkem'!J22 -> 24 | M22: 24 | N22: 0 | O22: ='Moduly - práce celkem'!K22 -> 0 | P22: 0 | Q22: 0 | R22: ='Moduly - práce celkem'!L22 -> 4 | S22: 4 | T22: 0 | U22: =I22+L22+O22+R22 -> 52 | V22: =M22*Analýza+J22*Konfigurace__vývoj+P22*Migrace+S22*Práva -> 52000 | W22: =N22*Analýza+K22*Konfigurace__vývoj+Q22*Migrace+T22*Práva -> 0 | X22: =L22*Analýza+I22*Konfigurace__vývoj+O22*Migrace+R22*Práva -> 52000
B23: Dispečink | C23: ý | D23: 0 | E23: 8 | F23: 32 | H23: ='Licence - moduly'!G25 -> 1 | I23: ='Moduly - práce celkem'!I23 -> 32 | J23: 32 | K23: 0 | L23: ='Moduly - práce celkem'!J23 -> 28 | M23: 28 | N23: 0 | O23: ='Moduly - práce celkem'!K23 -> 0 | P23: 0 | Q23: 0 | R23: ='Moduly - práce celkem'!L23 -> 4 | S23: 4 | T23: 0 | U23: =I23+L23+O23+R23 -> 64 | V23: =M23*Analýza+J23*Konfigurace__vývoj+P23*Migrace+S23*Práva -> 64000 | W23: =N23*Analýza+K23*Konfigurace__vývoj+Q23*Migrace+T23*Práva -> 0 | X23: =L23*Analýza+I23*Konfigurace__vývoj+O23*Migrace+R23*Práva -> 64000
B24: Servis | C24: ý | D24: 0 | E24: 8 | F24: 32 | H24: ='Licence - moduly'!G26 -> 1 | I24: ='Moduly - práce celkem'!I24 -> 32 | J24: 32 | K24: 0 | L24: ='Moduly - práce celkem'!J24 -> 32 | M24: 32 | N24: 0 | O24: ='Moduly - práce celkem'!K24 -> 0 | P24: 0 | Q24: 0 | R24: ='Moduly - práce celkem'!L24 -> 4 | S24: 4 | T24: 0 | U24: =I24+L24+O24+R24 -> 68 | V24: =M24*Analýza+J24*Konfigurace__vývoj+P24*Migrace+S24*Práva -> 68000 | W24: =N24*Analýza+K24*Konfigurace__vývoj+Q24*Migrace+T24*Práva -> 0 | X24: =L24*Analýza+I24*Konfigurace__vývoj+O24*Migrace+R24*Práva -> 68000
A25: Reporting | B25: Business Intelligence | C25: ý | D25: 16 | E25: 40 | F25: 120 | G25: Počítáno dle složitosti implementovaných analýz | H25: ='Licence - moduly'!G27 -> 1 | I25: ='Moduly - práce celkem'!I25 -> 80 | J25: 80 | K25: 0 | L25: ='Moduly - práce celkem'!J25 -> 80 | M25: 80 | N25: 0 | O25: ='Moduly - práce celkem'!K25 -> 0 | P25: 0 | Q25: 0 | R25: ='Moduly - práce celkem'!L25 -> 8 | S25: 8 | T25: 0 | U25: =I25+L25+O25+R25 -> 168 | V25: =M25*Analýza+J25*Konfigurace__vývoj+P25*Migrace+S25*Práva -> 168000 | W25: =N25*Analýza+K25*Konfigurace__vývoj+Q25*Migrace+T25*Práva -> 0 | X25: =L25*Analýza+I25*Konfigurace__vývoj+O25*Migrace+R25*Práva -> 168000
B26: Uživatelský portál | C26: ý | D26: 8 | E26: 4 | F26: 40 | G26: min. = jednoduchá agenda, max. = složitější sada stránek | H26: ='Licence - moduly'!G28 -> 1 | I26: ='Moduly - práce celkem'!I26 -> 40 | J26: 40 | K26: 0 | L26: ='Moduly - práce celkem'!J26 -> 32 | M26: 32 | N26: 0 | O26: ='Moduly - práce celkem'!K26 -> 0 | P26: 0 | Q26: 0 | R26: ='Moduly - práce celkem'!L26 -> 4 | S26: 4 | T26: 0 | U26: =I26+L26+O26+R26 -> 76 | V26: =M26*Analýza+J26*Konfigurace__vývoj+P26*Migrace+S26*Práva -> 76000 | W26: =N26*Analýza+K26*Konfigurace__vývoj+Q26*Migrace+T26*Práva -> 0 | X26: =L26*Analýza+I26*Konfigurace__vývoj+O26*Migrace+R26*Práva -> 76000
B27: Tvorba reportů | C27: þ | D27: 0 | E27: 1 | F27: 32 | G27: Počítáno za jeden report | H27: ='Licence - moduly'!G29 -> 1 | I27: ='Moduly - práce celkem'!I27 -> 24 | J27: 24 | K27: 0 | L27: ='Moduly - práce celkem'!J27 -> 24 | M27: 24 | N27: 0 | O27: ='Moduly - práce celkem'!K27 -> 0 | P27: 0 | Q27: 0 | R27: ='Moduly - práce celkem'!L27 -> 4 | S27: 4 | T27: 0 | U27: =I27+L27+O27+R27 -> 52 | V27: =M27*Analýza+J27*Konfigurace__vývoj+P27*Migrace+S27*Práva -> 52000 | W27: =N27*Analýza+K27*Konfigurace__vývoj+Q27*Migrace+T27*Práva -> 0 | X27: =L27*Analýza+I27*Konfigurace__vývoj+O27*Migrace+R27*Práva -> 52000
A28: Vlastní vývoj | B28: Uživatelský vývoj | C28: ý | D28: 0 | E28: ? | F28: ? | G28: Individuálně dle rozsahu a složitosti nových funkčností | H28: ='Licence - moduly'!G30 -> 1 | I28: ='Moduly - práce celkem'!I28 -> 40 | J28: 40 | K28: 0 | L28: ='Moduly - práce celkem'!J28 -> 40 | M28: 40 | N28: 0 | O28: ='Moduly - práce celkem'!K28 -> 0 | P28: 0 | Q28: 0 | R28: ='Moduly - práce celkem'!L28 -> 4 | S28: 4 | T28: 0 | U28: =I28+L28+O28+R28 -> 84 | V28: =M28*Analýza+J28*Konfigurace__vývoj+P28*Migrace+S28*Práva -> 84000 | W28: =N28*Analýza+K28*Konfigurace__vývoj+Q28*Migrace+T28*Práva -> 0 | X28: =L28*Analýza+I28*Konfigurace__vývoj+O28*Migrace+R28*Práva -> 84000
B29: Webové služby | C29: ý | D29: 0 | E29: 4 | F29: 24 | G29: Počítáno za jedno připojení | H29: ='Licence - moduly'!G31 -> 1 | I29: ='Moduly - práce celkem'!I29 -> 24 | J29: 24 | K29: 0 | L29: ='Moduly - práce celkem'!J29 -> 20 | M29: 20 | N29: 0 | O29: ='Moduly - práce celkem'!K29 -> 0 | P29: 0 | Q29: 0 | R29: ='Moduly - práce celkem'!L29 -> 0 | S29: 0 | T29: 0 | U29: =I29+L29+O29+R29 -> 44 | V29: =M29*Analýza+J29*Konfigurace__vývoj+P29*Migrace+S29*Práva -> 44000 | W29: =N29*Analýza+K29*Konfigurace__vývoj+Q29*Migrace+T29*Práva -> 0 | X29: =L29*Analýza+I29*Konfigurace__vývoj+O29*Migrace+R29*Práva -> 44000
B30: Export/Import | C30: þ | D30: 0 | E30: 1 | F30: 24 | G30: Počítáno za jeden export/import | H30: ='Licence - moduly'!G32 -> 1 | I30: ='Moduly - práce celkem'!I30 -> 16 | J30: 16 | K30: 0 | L30: ='Moduly - práce celkem'!J30 -> 16 | M30: 16 | N30: 0 | O30: ='Moduly - práce celkem'!K30 -> 0 | P30: 0 | Q30: 0 | R30: ='Moduly - práce celkem'!L30 -> 0 | S30: 0 | T30: 0 | U30: =I30+L30+O30+R30 -> 32 | V30: =M30*Analýza+J30*Konfigurace__vývoj+P30*Migrace+S30*Práva -> 32000 | W30: =N30*Analýza+K30*Konfigurace__vývoj+Q30*Migrace+T30*Práva -> 0 | X30: =L30*Analýza+I30*Konfigurace__vývoj+O30*Migrace+R30*Práva -> 32000
G31: Součet před korekcí: | I31: =SUM(I2:I30) -> 520 | J31: =SUM(J2:J30) -> 520 | K31: =SUM(K2:K30) -> 0 | L31: =SUM(L2:L30) -> 492 | M31: =SUM(M2:M30) -> 492 | N31: =SUM(N2:N30) -> 0 | O31: =SUM(O2:O30) -> 28 | P31: =SUM(P2:P30) -> 28 | ... X31: =SUM(X2:X30) -> 1122000
G32: Součet po korekci | I32: =I31*Koeficient_korekce -> 780 | J32: =J31*Koeficient_korekce -> 780 | K32: =K31*Koeficient_korekce -> 0 | L32: =L31*Koeficient_korekce -> 738 | M32: =M31*Koeficient_korekce -> 738 | N32: =N31*Koeficient_korekce -> 0 | O32: =O31*Koeficient_korekce -> 42 | P32: =P31*Koeficient_korekce -> 42 | ... X32: =X31*Koeficient_korekce -> 1683000
G33: Součet man days | J33: =J32/8 -> 97.5 | K33: =K32/8 -> 0 | M33: =M32/8 -> 92.25 | N33: =N32/8 -> 0 | P33: =P32/8 -> 5.25 | Q33: =Q32/8 -> 0 | S33: =S32/8 -> 15.375 | T33: =T32/8 -> 0
J34: Konfigurace | M34: Analýza (analýza + návrh) | P34: Migrace | S34: Práva
G36: Analýza a konfigurace se v čase prolínají (viz Ganttův diagram - návrh končí o cca. týden později - uzavření soupisu + zpětná vazba)

Sheet Obvyklý průběh implementace
A1: Další práce, spojené s realizací systému
A3: Fáze | B3: Činnost | C3: Zahrnuto v odhadech práce modulů | D3: Odhad Etapa 1 (člh) | E3: Cena Etapa 1 | F3: Odhad Etapa 2 (člh) | G3: Cena Etapa 2 | H3: Odhad celkem (člh) | I3: Cena celkem | J3: Součinnost Etapa 1 (člh) | K3: Součinnost Etapa 2 (člh) | L3: Součinnost celkem (člh) | M3: Poznámka
A4: Analýza | B4: Prezentace systému a jeho možností | C4: 0 | D4: 0 | E4: =D4*Analýza -> 0 | F4: 0 | G4: =F4*Analýza -> 0 | H4: =D4+F4 -> 0 | I4: =E4+G4 -> 0 | J4: 0 | K4: 0 | L4: =J4+K4 -> 0
B5: Konzultace s uživateli | C5: Analýza | D5: 0 | E5: 0 | F5: 0 | G5: 0 | H5: =D5+F5 -> 0 | I5: =E5+G5 -> 0 | J5: 80 | K5: ='Moduly - práce etapy'!N32 -> 0 | L5: =J5+K5 -> 80
B6: Soupis požadavků na systém | C6: Analýza | D6: 0 | E6: 0 | F6: 0 | G6: 0 | H6: =D6+F6 -> 0 | I6: =E6+G6 -> 0 | J6: 20 | K6: 0 | L6: =J6+K6 -> 20
B7: Diskuse a zpětná vazba | C7: Analýza | D7: 0 | E7: 0 | F7: 0 | G7: 0 | H7: =D7+F7 -> 0 | I7: =E7+G7 -> 0 | J7: 0 | K7: 0 | L7: =J7+K7 -> 0
B8: Požadavky na migraci | C8: Migrace | D8: 0 | E8: 0 | F8: 0 | G8: 0 | H8: =D8+F8 -> 0 | I8: =E8+G8 -> 0 | J8: =ROUNDUP('Moduly - práce etapy'!P32/2,0) -> 21 | K8: =ROUNDUP('Moduly - práce etapy'!Q32/2,0) -> 0 | L8: =J8+K8 -> 21
B9: Požadavky na přístupová práva | C9: Práva | D9: 0 | E9: 0 | F9: 0 | G9: 0 | H9: =D9+F9 -> 0 | I9: =E9+G9 -> 0 | J9: =ROUNDUP('Moduly - práce etapy'!S32/2,0) -> 62 | K9: =ROUNDUP('Moduly - práce etapy'!T32/2,0) -> 0 | L9: =J9+K9 -> 62
A10: Návrh | B10: Výběr modulů | C10: 0 | D10: 0 | E10: =D10*Analýza -> 0 | F10: 0 | G10: =F10*Analýza -> 0 | H10: =D10+F10 -> 0 | I10: =E10+G10 -> 0 | J10: 0 | K10: 0 | L10: =J10+K10 -> 0
B11: Příprava konfigurace | C11: Analýza | D11: 0 | E11: 0 | F11: 0 | G11: 0 | H11: =D11+F11 -> 0 | I11: =E11+G11 -> 0 | J11: 0 | K11: 0 | L11: =J11+K11 -> 0
B12: Definice vývoje nových funkčností | C12: Analýza | D12: 0 | E12: 0 | F12: 0 | G12: 0 | H12: =D12+F12 -> 0 | I12: =E12+G12 -> 0 | J12: 0 | K12: 0 | L12: =J12+K12 -> 0
B13: Vytvoření dokumentace | C13: Analýza | D13: 0 | E13: 0 | F13: 0 | G13: 0 | H13: =D13+F13 -> 0 | I13: =E13+G13 -> 0 | J13: 40 | K13: 0 | L13: =J13+K13 -> 40
B14: Diskuse a zpětná vazba k návrhu | C14: 0 | D14: 16 | E14: =D14*Analýza -> 16000 | F14: 0 | G14: =F14*Analýza -> 0 | H14: =D14+F14 -> 16 | I14: =E14+G14 -> 16000 | J14: 0 | K14: 0 | L14: =J14+K14 -> 0
B15: Návrh migrace | C15: Migrace | D15: 0 | E15: 0 | F15: 0 | G15: 0 | H15: =D15+F15 -> 0 | I15: =E15+G15 -> 0 | J15: 0 | K15: 0 | L15: =J15+K15 -> 0
B16: Návrh přístupových práv | C16: Práva | D16: 0 | E16: 0 | F16: 0 | G16: 0 | H16: =D16+F16 -> 0 | I16: =E16+G16 -> 0 | J16: 0 | K16: 0 | L16: =J16+K16 -> 0
A17: Implementace | B17: Instalace systému | C17: 0 | D17: 16 | E17: =D17*Ostatní -> 16000 | F17: 0 | G17: =F17*Ostatní -> 0 | H17: =D17+F17 -> 16 | I17: =E17+G17 -> 16000 | J17: 0 | K17: 0 | L17: =J17+K17 -> 0
B18: Konfigurace existujících modulů | C18: Konfigurace | D18: 0 | E18: 0 | F18: 0 | G18: 0 | H18: =D18+F18 -> 0 | I18: =E18+G18 -> 0 | J18: 0 | K18: 0 | L18: =J18+K18 -> 0
B19: Vývoj nové funkčnosti | C19: Implementace | D19: 0 | E19: 0 | F19: 0 | G19: 0 | H19: =D19+F19 -> 0 | I19: =E19+G19 -> 0 | J19: 0 | K19: 0 | L19: =J19+K19 -> 0
B20: Integrace nové funkčnosti do systému | C20: Implementace | D20: 0 | E20: 0 | F20: 0 | G20: 0 | H20: =D20+F20 -> 0 | I20: =E20+G20 -> 0 | J20: 0 | K20: 0 | L20: =J20+K20 -> 0
B21: Průběžné testování funkčnosti | C21: Funkční testy | D21: 0 | E21: 0 | F21: 0 | G21: 0 | H21: =D21+F21 -> 0 | I21: =E21+G21 -> 0 | J21: 0 | K21: 0 | L21: =J21+K21 -> 0
B22: Příprava uživatelské dokumentace | C22: 0 | D22: 40 | E22: =D22*Tvorba_dokumentace -> 32000 | F22: 0 | G22: =F22*Tvorba_dokumentace -> 0 | H22: =D22+F22 -> 40 | I22: =E22+G22 -> 32000 | J22: 0 | K22: 0 | L22: =J22+K22 -> 0
B23: Příprava migrace | C23: Migrace | D23: 0 | E23: 0 | F23: 0 | G23: 0 | H23: =D23+F23 -> 0 | I23: =E23+G23 -> 0 | J23: 0 | K23: 0 | L23: =J23+K23 -> 0
A24: Uživatelské testování | B24: Příprava systému pro testování | C24: 0 | D24: 16 | E24: =D24*Ostatní -> 16000 | F24: 0 | G24: =F24*Ostatní -> 0 | H24: =D24+F24 -> 16 | I24: =E24+G24 -> 16000 | J24: 0 | K24: 0 | L24: =J24+K24 -> 0
B25: Zprovoznění klientů pro uživatelské testování | C25: 0 | D25: 8 | E25: =D25*Ostatní -> 8000 | F25: 0 | G25: =F25*Ostatní -> 0 | H25: =D25+F25 -> 8 | I25: =E25+G25 -> 8000 | J25: 0 | K25: 0 | L25: =J25+K25 -> 0
B26: Integrace do prostředí zákazníka | C26: Integrace | D26: 0 | E26: 0 | F26: 0 | G26: 0 | H26: =D26+F26 -> 0 | I26: =E26+G26 -> 0 | J26: 0 | K26: 0 | L26: =J26+K26 -> 0
B27: Zkušební migrace dat | C27: Migrace | D27: 0 | E27: 0 | F27: 0 | G27: 0 | H27: =D27+F27 -> 0 | I27: =E27+G27 -> 0 | J27: 16 | K27: 0 | L27: =J27+K27 -> 16
B28: Nastavení a ověření přístupových práv | C28: Práva | D28: 0 | E28: 0 | F28: 0 | G28: 0 | H28: =D28+F28 -> 0 | I28: =E28+G28 -> 0 | J28: 0 | K28: 0 | L28: =J28+K28 -> 0
B29: Zaškolení uživatelů před uživatelským testováním | C29: 0 | D29: 16 | E29: =D29*Analýza -> 16000 | F29: 0 | G29: =F29*Analýza -> 0 | H29: =D29+F29 -> 16 | I29: =E29+G29 -> 16000 | J29: 24 | K29: 0 | L29: =J29+K29 -> 24
B30: Testování uživateli | C30: 0 | D30: 24 | E30: =D30*Analýza -> 24000 | F30: 0 | G30: =F30*Analýza -> 0 | H30: =D30+F30 -> 24 | I30: =E30+G30 -> 24000 | J30: 80 | K30: 0 | L30: =J30+K30 -> 80
B31: Finalizace uživatelské dokumentace | C31: 0 | D31: 40 | E31: =D31*Tvorba_dokumentace -> 32000 | F31: 0 | G31: =F31*Tvorba_dokumentace -> 0 | H31: =D31+F31 -> 40 | I31: =E31+G31 -> 32000 | J31: 0 | K31: 0 | L31: =J31+K31 -> 0
B32: Průběžná aktualizace systému dle nových požadavků a opravy chyb | C32: Implementace | D32: 0 | E32: =D32*Analýza -> 0 | F32: 0 | G32: =F32*Analýza -> 0 | H32: =D32+F32 -> 0 | I32: =E32+G32 -> 0 | J32: 0 | K32: 0 | L32: =J32+K32 -> 0
A33: Nasazení | B33: Příprava systému pro reálný provoz | C33: 0 | D33: 16 | E33: =D33*Ostatní -> 16000 | F33: 0 | G33: =F33*Ostatní -> 0 | H33: =D33+F33 -> 16 | I33: =E33+G33 -> 16000 | J33: 0 | K33: 0 | L33: =J33+K33 -> 0
B34: Zprovoznění klientů pro reálný provoz | C34: 0 | D34: 24 | E34: =D34*Ostatní -> 24000 | F34: 0 | G34: =F34*Ostatní -> 0 | H34: =D34+F34 -> 24 | I34: =E34+G34 -> 24000 | J34: 0 | K34: 0 | L34: =J34+K34 -> 0
B35: Finální migrace dat | C35: Migrace | D35: 0 | E35: 0 | F35: 0 | G35: 0 | H35: =D35+F35 -> 0 | I35: =E35+G35 -> 0 | J35: 0 | K35: 0 | L35: =J35+K35 -> 0
B36: FInální nastavení přístupových práv | C36: Práva | D36: 0 | E36: 0 | F36: 0 | G36: 0 | H36: =D36+F36 -> 0 | I36: =E36+G36 -> 0 | J36: 0 | K36: 0 | L36: =J36+K36 -> 0
B37: Školení před nasazením do reálného provozu | C37: 0 | D37: 24 | E37: =D37*Analýza -> 24000 | F37: 0 | G37: =F37*Analýza -> 0 | H37: =D37+F37 -> 24 | I37: =E37+G37 -> 24000 | J37: 1200 | K37: 0 | L37: =J37+K37 -> 1200
B38: Pilotní provoz | C38: 0 | D38: 40 | E38: =D38*Analýza -> 40000 | F38: 0 | G38: =F38*Analýza -> 0 | H38: =D38+F38 -> 40 | I38: =E38+G38 -> 40000 | J38: 160 | K38: 0 | L38: =J38+K38 -> 160
B39: Zvýšená podpora při nasazení | C39: 0 | D39: 400 | E39: =D39*Analýza -> 400000 | F39: 0 | G39: =F39*Analýza -> 0 | H39: =D39+F39 -> 400 | I39: =E39+G39 -> 400000 | J39: 0 | K39: 0 | L39: =J39+K39 -> 0
A40: Projektové řízení | B40: Vedoucí projektu | C40: 0 | D40: 120 | E40: =D40*Vedení_projektu -> 180000 | F40: 0 | G40: =F40*Vedení_projektu -> 0 | H40: =D40+F40 -> 120 | I40: =E40+G40 -> 180000 | J40: 80 | K40: 0 | L40: =J40+K40 -> 80
B41: Komunikace a koordinace týmu | C41: 0 | D41: 40 | E41: =D41*(2*Analýza+Ostatní+Vedení_projektu) -> 180000 | F41: 0 | G41: =F41*(2*Analýza+Ostatní+Vedení_projektu+Konfigurace__vývoj) -> 0 | H41: =D41+F41 -> 40 | I41: =E41+G41 -> 180000 | J41: 0 | K41: 0 | L41: =J41+K41 -> 0
...

Sheet Celkem za implementaci
A1: Doplňkové položky instalace
A3: Položka | B3: Cena za jednotku bez DPH | C3: Počet | D3: Celkem
A4: Instalace serveru | B4: 4000 | C4: 0 | D4: =B4*C4 -> 0 | E4: POZOR! Položka není nutná, protože byl vybrán instalační balíček
A5: Instalace databáze | B5: 4000 | C5: 0 | D5: =B5*C5 -> 0 | E5: POZOR! Položka není nutná, protože byl vybrán instalační balíček
A6: Instalační balíček databáze + aplikační server | B6: 6000 | C6: 0 | D6: =B6*C6 -> 0
A7: Rozšíření o další jazyk uživatelského rozhraní | B7: 10000 | C7: 1 | D7: =B7*C7 -> 10000
B8: Celkem ostatní náklady: | D8: =SUM(D4:D7) -> 10000
A10: Výsledná cena za implementaci
A12: Položka | B12: Cena (bez DPH)
A13: Licence | B13: ='Licence - moduly'!H61 -> 1390000
A14: Implementační práce Etapa 1 | B14: ='Moduly - práce etapy'!V32+'Obvyklý průběh implementace'!E43 -> 2725000
A15: Implementační práce Etapa 2 | B15: ='Moduly - práce etapy'!W32+'Obvyklý průběh implementace'!G43 -> 0
A16: Ostatní náklady | B16: =D8 -> 10000
A17: Implementace celkem | B17: =SUM(B13:B16) -> 4125000
A18: Maintenance poplatek (20% z licencí) | B18: ='Licence - moduly'!H62 -> 278000

Sheet Finanční analýza
A1: Finanční analýza za období implementace a následujících pěti let provozu
A3: Použitá diskontní sazba: | B3: 0.06
A5: Rok | B5: 0 | C5: 1 | D5: 2 | E5: 3 | F5: 4 | G5: 5
A6: Licence | B6: =-'Celkem za implementaci'!B13 -> -1390000 | K6: Obrat autoprodeje (Kč) | L6: 300000000
A7: Etapa 1 | B7: =-'Celkem za implementaci'!B14 -> -2725000 | K7: Získovost autoprodeje | L7: 0.08
A8: Etapa 2 | B8: =-'Celkem za implementaci'!B15 -> 0
A9: Ostatní náklady | B9: =-'Celkem za implementaci'!B16 -> -10000 | C9: 0 | D9: 0 | E9: 0 | F9: 0 | G9: 0 | K9: Zvyšení obratu autoprodeje 1. rok po spuštění | L9: 1.1
A10: Maintenance | C10: 0 | D10: =-'Celkem za implementaci'!B18 -> -278000 | E10: =-'Celkem za implementaci'!B18 -> -278000 | F10: =-'Celkem za implementaci'!B18 -> -278000 | G10: =-'Celkem za implementaci'!B18 -> -278000 | K10: Úspory v autoprodeji 1. rok po spuštění (Kč) | L10: =L6*L9*L7-(L6*L7) -> 2400000
A11: Podpora | B11: -480000 | C11: -480000 | D11: -480000 | E11: -480000 | F11: -480000 | G11: -480000
A12: Úspory | C12: =L29 -> 4500000 | D12: =L30 -> 9800000 | E12: =L30 -> 9800000 | F12: =L30 -> 9800000 | G12: =L30 -> 9800000 | K12: Zvyšení obratu autoprodeje 2. rok po spuštění | L12: 1.2
A13: CF | B13: =SUM(B6:B12) -> -4605000 | C13: =SUM(C6:C12) -> 4020000 | D13: =SUM(D6:D12) -> 9042000 | E13: =SUM(E6:E12) -> 9042000 | F13: =SUM(F6:F12) -> 9042000 | G13: =SUM(G6:G12) -> 9042000 | K13: Úspory v autoprodeji 2. rok po spuštění (Kč) | L13: =L6*L7*L12-(L6*L7) -> 4800000
A14: DCF | B14: =B13/POWER((1+Diskont),B5) -> -4605000 | C14: =C13/POWER((1+Diskont),C5) -> 3792452.8 | D14: =D13/POWER((1+Diskont),D5) -> 8047347.8 | E14: =E13/POWER((1+Diskont),E5) -> 7591837.6 | F14: =F13/POWER((1+Diskont),F5) -> 7162110.9 | G14: =G13/POWER((1+Diskont),G5) -> 6756708.4
A15: Náklady celkem (za 5 let) | G15: =-(SUM(B6:B9)+SUM(C10:G10)+SUM(C11:G11)) -> 7637000 | H15: (bez započítání diskontu)
A16: Úspory celkem (za 5 let) | G16: =SUM(C12:G12) -> 43700000 | K16: Obrat autoservisu (Kč) | L16: 70000000
A17: NPV | G17: =SUM(B14:G14) -> 28745458 | K17: Získovost autoservisu | L17: 0.3
A18: ROI* | G18: =(G16-G15)/G15 -> 4.7221422 | H18: (za dobu pěti let provozu systému)
K19: Zvyšení obratu autoservisu 1. rok po spuštění | L19: 1.1
A20: *ROI = ((úspory celkem - náklady celkem)/náklady celkem)*100 | K20: Úspory v autoservisu 1. rok po spuštění (Kč) | L20: =L16*L19*L17-(L16*L17) -> 2100000
A22: Součinnost | B22: člh | K22: Zvyšení obratu autoservisu 2. - 5. rok po spuštění | L22: 1.2
A23: Etapa 1 | B23: ='Obvyklý průběh implementace'!J43 -> 1795 | K23: Úspory v autoservisu 2. - 5. rok po spuštění (Kč) | L23: =L16*L17*L22-(L16*L17) -> 4200000
A24: Etapa 2 | B24: ='Obvyklý průběh implementace'!K43 -> 0
A25: Celkem: | B25: ='Obvyklý průběh implementace'!L43 -> 1795
K26: Roční úspory na náboru nových zaměstnanců 2. - 5. rok po spuštění (Kč) | L26: 800000
K29: Celkové úspory 1. rok po spuštění (Kč) | L29: =L10+L20 -> 4500000
K30: Celkové úspory 2. - 5. rok po spuštění (Kč) | L30: =L13+L23+L26 -> 9800000
